File: exercise3/PerfectPlasticity2/PerfectPlasticity2/elastic_results.dat
# Axial_Strain, Deviatoric_Stress (kPa)
       0.000000       0.000000
       0.000100       1.000000
       0.000200       2.000000
       0.000300       3.000000
       0.000400       4.000000
       0.000500       5.000000
       0.000600       6.000000
       0.000700       7.000000
       0.000800       8.000000
       0.000900       9.000000
       0.001000      10.000000
       0.001100      11.000000
       0.001200      12.000000
       0.001300      13.000000
       0.001400      14.000000
       0.001500      15.000000
       0.001600      16.000000
       0.001700      17.000000
       0.001800      18.000000
       0.001900      19.000000
       0.002000      20.000000
       0.002100      21.000000
       0.002200      22.000000
       0.002300      23.000000
       0.002400      24.000000
       0.002500      25.000000
       0.002600      26.000000
       0.002700      27.000000
       0.002800      28.000000
       0.002900      29.000000
       0.003000      30.000000
       0.003100      31.000000
       0.003200      32.000000
       0.003300      33.000000
       0.003400      34.000000
       0.003500      35.000000
       0.003600      36.000000
       0.003700      37.000000
       0.003800      38.000000
       0.003900      39.000000
       0.004000      40.000000
       0.004100      41.000000
       0.004200      42.000000
       0.004300      43.000000
       0.004400      44.000000
       0.004500      45.000000
       0.004600      46.000000
       0.004700      47.000000
       0.004800      48.000000
       0.004900      49.000000
       0.005000      50.000000
       0.005100      51.000000
       0.005200      52.000000
       0.005300      53.000000
       0.005400      54.000000
       0.005500      55.000000
       0.005600      56.000000
       0.005700      57.000000
       0.005800      58.000000
       0.005900      59.000000
       0.006000      60.000000
       0.006100      61.000000
       0.006200      62.000000
       0.006300      63.000000
       0.006400      64.000000
       0.006500      65.000000
       0.006600      66.000000
       0.006700      67.000000
       0.006800      68.000000
       0.006900      69.000000
       0.007000      70.000000
       0.007100      71.000000
       0.007200      72.000000
       0.007300      73.000000
       0.007400      74.000000
       0.007500      75.000000
       0.007600      76.000000
       0.007700      77.000000
       0.007800      78.000000
       0.007900      79.000000
       0.008000      80.000000
       0.008100      81.000000
       0.008200      82.000000
       0.008300      83.000000
       0.008400      84.000000
       0.008500      85.000000
       0.008600      86.000000
       0.008700      87.000000
       0.008800      88.000000
       0.008900      89.000000
       0.009000      90.000000
       0.009100      91.000000
       0.009200      92.000000
       0.009300      93.000000
       0.009400      94.000000
       0.009500      95.000000
       0.009600      96.000000
       0.009700      97.000000
       0.009800      98.000000
       0.009900      99.000000
       0.010000     100.000000
       0.010100     101.000000
       0.010200     102.000000
       0.010300     103.000000
       0.010400     104.000000
       0.010500     105.000000
       0.010600     106.000000
       0.010700     107.000000
       0.010800     108.000000
       0.010900     109.000000
       0.011000     110.000000
       0.011100     111.000000
       0.011200     112.000000
       0.011300     113.000000
       0.011400     114.000000
       0.011500     115.000000
       0.011600     116.000000
       0.011700     117.000000
       0.011800     118.000000
       0.011900     119.000000
       0.012000     120.000000
       0.012100     121.000000
       0.012200     122.000000
       0.012300     123.000000
       0.012400     124.000000
       0.012500     125.000000
       0.012600     126.000000
       0.012700     127.000000
       0.012800     128.000000
       0.012900     129.000000
       0.013000     130.000000
       0.013100     131.000000
       0.013200     132.000000
       0.013300     133.000000
       0.013400     134.000000
       0.013500     135.000000
       0.013600     136.000000
       0.013700     137.000000
       0.013800     138.000000
       0.013900     139.000000
       0.014000     140.000000
       0.014100     141.000000
       0.014200     142.000000
       0.014300     143.000000
       0.014400     144.000000
       0.014500     145.000000
       0.014600     146.000000
       0.014700     147.000000
       0.014800     148.000000
       0.014900     149.000000
       0.015000     150.000000
       0.015100     151.000000
       0.015200     152.000000
       0.015300     153.000000
       0.015400     154.000000
       0.015500     155.000000
       0.015600     156.000000
       0.015700     157.000000
       0.015800     158.000000
       0.015900     159.000000
       0.016000     160.000000
       0.016100     161.000000
       0.016200     162.000000
       0.016300     163.000000
       0.016400     164.000000
       0.016500     165.000000
       0.016600     166.000000
       0.016700     167.000000
       0.016800     168.000000
       0.016900     169.000000
       0.017000     170.000000
       0.017100     171.000000
       0.017200     172.000000
       0.017300     173.000000
       0.017400     174.000000
       0.017500     175.000000
       0.017600     176.000000
       0.017700     177.000000
       0.017800     178.000000
       0.017900     179.000000
       0.018000     180.000000
       0.018100     181.000000
       0.018200     182.000000
       0.018300     183.000000
       0.018400     184.000000
       0.018500     185.000000
       0.018600     186.000000
       0.018700     187.000000
       0.018800     188.000000
       0.018900     189.000000
       0.019000     190.000000
       0.019100     191.000000
       0.019200     192.000000
       0.019300     193.000000
       0.019400     194.000000
       0.019500     195.000000
       0.019600     196.000000
       0.019700     197.000000
       0.019800     198.000000
       0.019900     199.000000
       0.020000     200.000000
       0.020100     201.000000
       0.020200     202.000000
       0.020300     203.000000
       0.020400     204.000000
       0.020500     205.000000
       0.020600     206.000000
       0.020700     207.000000
       0.020800     208.000000
       0.020900     209.000000
       0.021000     210.000000
       0.021100     211.000000
       0.021200     212.000000
       0.021300     213.000000
       0.021400     214.000000
       0.021500     215.000000
       0.021600     216.000000
       0.021700     217.000000
       0.021800     218.000000
       0.021900     219.000000
       0.022000     220.000000
       0.022100     221.000000
       0.022200     222.000000
       0.022300     223.000000
       0.022400     224.000000
       0.022500     225.000000
       0.022600     226.000000
       0.022700     227.000000
       0.022800     228.000000
       0.022900     229.000000
       0.023000     230.000000
       0.023100     231.000000
       0.023200     232.000000
       0.023300     233.000000
       0.023400     234.000000
       0.023500     235.000000
       0.023600     236.000000
       0.023700     237.000000
       0.023800     238.000000
       0.023900     239.000000
       0.024000     240.000000
       0.024100     241.000000
       0.024200     242.000000
       0.024300     243.000000
       0.024400     244.000000
       0.024500     245.000000
       0.024600     246.000000
       0.024700     247.000000
       0.024800     248.000000
       0.024900     249.000000
       0.025000     250.000000
       0.025100     251.000000
       0.025200     252.000000
       0.025300     253.000000
       0.025400     254.000000
       0.025500     255.000000
       0.025600     256.000000
       0.025700     257.000000
       0.025800     258.000000
       0.025900     259.000000
       0.026000     260.000000
       0.026100     261.000000
       0.026200     262.000000
       0.026300     263.000000
       0.026400     264.000000
       0.026500     265.000000
       0.026600     266.000000
       0.026700     267.000000
       0.026800     268.000000
       0.026900     269.000000
       0.027000     270.000000
       0.027100     271.000000
       0.027200     272.000000
       0.027300     273.000000
       0.027400     274.000000
       0.027500     275.000000
       0.027600     276.000000
       0.027700     277.000000
       0.027800     278.000000
       0.027900     279.000000
       0.028000     280.000000
       0.028100     281.000000
       0.028200     282.000000
       0.028300     283.000000
       0.028400     284.000000
       0.028500     285.000000
       0.028600     286.000000
       0.028700     287.000000
       0.028800     288.000000
       0.028900     289.000000
       0.029000     290.000000
       0.029100     291.000000
       0.029200     292.000000
       0.029300     293.000000
       0.029400     294.000000
       0.029500     295.000000
       0.029600     296.000000
       0.029700     297.000000
       0.029800     298.000000
       0.029900     299.000000
       0.030000     300.000000
       0.030100     301.000000
       0.030200     302.000000
       0.030300     303.000000
       0.030400     304.000000
       0.030500     305.000000
       0.030600     306.000000
       0.030700     307.000000
       0.030800     308.000000
       0.030900     309.000000
       0.031000     310.000000
       0.031100     311.000000
       0.031200     312.000000
       0.031300     313.000000
       0.031400     314.000000
       0.031500     315.000000
       0.031600     316.000000
       0.031700     317.000000
       0.031800     318.000000
       0.031900     319.000000
       0.032000     320.000000
       0.032100     321.000000
       0.032200     322.000000
       0.032300     323.000000
       0.032400     324.000000
       0.032500     325.000000
       0.032600     326.000000
       0.032700     327.000000
       0.032800     328.000000
       0.032900     329.000000
       0.033000     330.000000
       0.033100     331.000000
       0.033200     332.000000
       0.033300     333.000000
       0.033400     334.000000
       0.033500     335.000000
       0.033600     336.000000
       0.033700     337.000000
       0.033800     338.000000
       0.033900     339.000000
       0.034000     340.000000
       0.034100     341.000000
       0.034200     342.000000
       0.034300     343.000000
       0.034400     344.000000
       0.034500     345.000000
       0.034600     346.000000
       0.034700     347.000000
       0.034800     348.000000
       0.034900     349.000000
       0.035000     350.000000
       0.035100     351.000000
       0.035200     352.000000
       0.035300     353.000000
       0.035400     354.000000
       0.035500     355.000000
       0.035600     356.000000
       0.035700     357.000000
       0.035800     358.000000
       0.035900     359.000000
       0.036000     360.000000
       0.036100     361.000000
       0.036200     362.000000
       0.036300     363.000000
       0.036400     364.000000
       0.036500     365.000000
       0.036600     366.000000
       0.036700     367.000000
       0.036800     368.000000
       0.036900     369.000000
       0.037000     370.000000
       0.037100     371.000000
       0.037200     372.000000
       0.037300     373.000000
       0.037400     374.000000
       0.037500     375.000000
       0.037600     376.000000
       0.037700     377.000000
       0.037800     378.000000
       0.037900     379.000000
       0.038000     380.000000
       0.038100     381.000000
       0.038200     382.000000
       0.038300     383.000000
       0.038400     384.000000
       0.038500     385.000000
       0.038600     386.000000
       0.038700     387.000000
       0.038800     388.000000
       0.038900     389.000000
       0.039000     390.000000
       0.039100     391.000000
       0.039200     392.000000
       0.039300     393.000000
       0.039400     394.000000
       0.039500     395.000000
       0.039600     396.000000
       0.039700     397.000000
       0.039800     398.000000
       0.039900     399.000000
       0.040000     400.000000
       0.040100     401.000000
       0.040200     402.000000
       0.040300     403.000000
       0.040400     404.000000
       0.040500     405.000000
       0.040600     406.000000
       0.040700     407.000000
       0.040800     408.000000
       0.040900     409.000000
       0.041000     410.000000
       0.041100     411.000000
       0.041200     412.000000
       0.041300     413.000000
       0.041400     414.000000
       0.041500     415.000000
       0.041600     416.000000
       0.041700     417.000000
       0.041800     418.000000
       0.041900     419.000000
       0.042000     420.000000
       0.042100     421.000000
       0.042200     422.000000
       0.042300     423.000000
       0.042400     424.000000
       0.042500     425.000000
       0.042600     426.000000
       0.042700     427.000000
       0.042800     428.000000
       0.042900     429.000000
       0.043000     430.000000
       0.043100     431.000000
       0.043200     432.000000
       0.043300     433.000000
       0.043400     434.000000
       0.043500     435.000000
       0.043600     436.000000
       0.043700     437.000000
       0.043800     438.000000
       0.043900     439.000000
       0.044000     440.000000
       0.044100     441.000000
       0.044200     442.000000
       0.044300     443.000000
       0.044400     444.000000
       0.044500     445.000000
       0.044600     446.000000
       0.044700     447.000000
       0.044800     448.000000
       0.044900     449.000000
       0.045000     450.000000
       0.045100     451.000000
       0.045200     452.000000
       0.045300     453.000000
       0.045400     454.000000
       0.045500     455.000000
       0.045600     456.000000
       0.045700     457.000000
       0.045800     458.000000
       0.045900     459.000000
       0.046000     460.000000
       0.046100     461.000000
       0.046200     462.000000
       0.046300     463.000000
       0.046400     464.000000
       0.046500     465.000000
       0.046600     466.000000
       0.046700     467.000000
       0.046800     468.000000
       0.046900     469.000000
       0.047000     470.000000
       0.047100     471.000000
       0.047200     472.000000
       0.047300     473.000000
       0.047400     474.000000
       0.047500     475.000000
       0.047600     476.000000
       0.047700     477.000000
       0.047800     478.000000
       0.047900     479.000000
       0.048000     480.000000
       0.048100     481.000000
       0.048200     482.000000
       0.048300     483.000000
       0.048400     484.000000
       0.048500     485.000000
       0.048600     486.000000
       0.048700     487.000000
       0.048800     488.000000
       0.048900     489.000000
       0.049000     490.000000
       0.049100     491.000000
       0.049200     492.000000
       0.049300     493.000000
       0.049400     494.000000
       0.049500     495.000000
       0.049600     496.000000
       0.049700     497.000000
       0.049800     498.000000
       0.049900     499.000000
       0.050000     500.000000
       0.050100     501.000000
       0.050200     502.000000
       0.050300     503.000000
       0.050400     504.000000
       0.050500     505.000000
       0.050600     506.000000
       0.050700     507.000000
       0.050800     508.000000
       0.050900     509.000000
       0.051000     510.000000
       0.051100     511.000000
       0.051200     512.000000
       0.051300     513.000000
       0.051400     514.000000
       0.051500     515.000000
       0.051600     516.000000
       0.051700     517.000000
       0.051800     518.000000
       0.051900     519.000000
       0.052000     520.000000
       0.052100     521.000000
       0.052200     522.000000
       0.052300     523.000000
       0.052400     524.000000
       0.052500     525.000000
       0.052600     526.000000
       0.052700     527.000000
       0.052800     528.000000
       0.052900     529.000000
       0.053000     530.000000
       0.053100     531.000000
       0.053200     532.000000
       0.053300     533.000000
       0.053400     534.000000
       0.053500     535.000000
       0.053600     536.000000
       0.053700     537.000000
       0.053800     538.000000
       0.053900     539.000000
       0.054000     540.000000
       0.054100     541.000000
       0.054200     542.000000
       0.054300     543.000000
       0.054400     544.000000
       0.054500     545.000000
       0.054600     546.000000
       0.054700     547.000000
       0.054800     548.000000
       0.054900     549.000000
       0.055000     550.000000
       0.055100     551.000000
       0.055200     552.000000
       0.055300     553.000000
       0.055400     554.000000
       0.055500     555.000000
       0.055600     556.000000
       0.055700     557.000000
       0.055800     558.000000
       0.055900     559.000000
       0.056000     560.000000
       0.056100     561.000000
       0.056200     562.000000
       0.056300     563.000000
       0.056400     564.000000
       0.056500     565.000000
       0.056600     566.000000
       0.056700     567.000000
       0.056800     568.000000
       0.056900     569.000000
       0.057000     570.000000
       0.057100     571.000000
       0.057200     572.000000
       0.057300     573.000000
       0.057400     574.000000
       0.057500     575.000000
       0.057600     576.000000
       0.057700     577.000000
       0.057800     578.000000
       0.057900     579.000000
       0.058000     580.000000
       0.058100     581.000000
       0.058200     582.000000
       0.058300     583.000000
       0.058400     584.000000
       0.058500     585.000000
       0.058600     586.000000
       0.058700     587.000000
       0.058800     588.000000
       0.058900     589.000000
       0.059000     590.000000
       0.059100     591.000000
       0.059200     592.000000
       0.059300     593.000000
       0.059400     594.000000
       0.059500     595.000000
       0.059600     596.000000
       0.059700     597.000000
       0.059800     598.000000
       0.059900     599.000000
       0.060000     600.000000
       0.060100     601.000000
       0.060200     602.000000
       0.060300     603.000000
       0.060400     604.000000
       0.060500     605.000000
       0.060600     606.000000
       0.060700     607.000000
       0.060800     608.000000
       0.060900     609.000000
       0.061000     610.000000
       0.061100     611.000000
       0.061200     612.000000
       0.061300     613.000000
       0.061400     614.000000
       0.061500     615.000000
       0.061600     616.000000
       0.061700     617.000000
       0.061800     618.000000
       0.061900     619.000000
       0.062000     620.000000
       0.062100     621.000000
       0.062200     622.000000
       0.062300     623.000000
       0.062400     624.000000
       0.062500     625.000000
       0.062600     626.000000
       0.062700     627.000000
       0.062800     628.000000
       0.062900     629.000000
       0.063000     630.000000
       0.063100     631.000000
       0.063200     632.000000
       0.063300     633.000000
       0.063400     634.000000
       0.063500     635.000000
       0.063600     636.000000
       0.063700     637.000000
       0.063800     638.000000
       0.063900     639.000000
       0.064000     640.000000
       0.064100     641.000000
       0.064200     642.000000
       0.064300     643.000000
       0.064400     644.000000
       0.064500     645.000000
       0.064600     646.000000
       0.064700     647.000000
       0.064800     648.000000
       0.064900     649.000000
       0.065000     650.000000
       0.065100     651.000000
       0.065200     652.000000
       0.065300     653.000000
       0.065400     654.000000
       0.065500     655.000000
       0.065600     656.000000
       0.065700     657.000000
       0.065800     658.000000
       0.065900     659.000000
       0.066000     660.000000
       0.066100     661.000000
       0.066200     662.000000
       0.066300     663.000000
       0.066400     664.000000
       0.066500     665.000000
       0.066600     666.000000
       0.066700     667.000000
       0.066800     668.000000
       0.066900     669.000000
       0.067000     670.000000
       0.067100     671.000000
       0.067200     672.000000
       0.067300     673.000000
       0.067400     674.000000
       0.067500     675.000000
       0.067600     676.000000
       0.067700     677.000000
       0.067800     678.000000
       0.067900     679.000000
       0.068000     680.000000
       0.068100     681.000000
       0.068200     682.000000
       0.068300     683.000000
       0.068400     684.000000
       0.068500     685.000000
       0.068600     686.000000
       0.068700     687.000000
       0.068800     688.000000
       0.068900     689.000000
       0.069000     690.000000
       0.069100     691.000000
       0.069200     692.000000
       0.069300     693.000000
       0.069400     694.000000
       0.069500     695.000000
       0.069600     696.000000
       0.069700     697.000000
       0.069800     698.000000
       0.069900     699.000000
       0.070000     700.000000
       0.070100     701.000000
       0.070200     702.000000
       0.070300     703.000000
       0.070400     704.000000
       0.070500     705.000000
       0.070600     706.000000
       0.070700     707.000000
       0.070800     708.000000
       0.070900     709.000000
       0.071000     710.000000
       0.071100     711.000000
       0.071200     712.000000
       0.071300     713.000000
       0.071400     714.000000
       0.071500     715.000000
       0.071600     716.000000
       0.071700     717.000000
       0.071800     718.000000
       0.071900     719.000000
       0.072000     720.000000
       0.072100     721.000000
       0.072200     722.000000
       0.072300     723.000000
       0.072400     724.000000
       0.072500     725.000000
       0.072600     726.000000
       0.072700     727.000000
       0.072800     728.000000
       0.072900     729.000000
       0.073000     730.000000
       0.073100     731.000000
       0.073200     732.000000
       0.073300     733.000000
       0.073400     734.000000
       0.073500     735.000000
       0.073600     736.000000
       0.073700     737.000000
       0.073800     738.000000
       0.073900     739.000000
       0.074000     740.000000
       0.074100     741.000000
       0.074200     742.000000
       0.074300     743.000000
       0.074400     744.000000
       0.074500     745.000000
       0.074600     746.000000
       0.074700     747.000000
       0.074800     748.000000
       0.074900     749.000000
       0.075000     750.000000
       0.075100     751.000000
       0.075200     752.000000
       0.075300     753.000000
       0.075400     754.000000
       0.075500     755.000000
       0.075600     756.000000
       0.075700     757.000000
       0.075800     758.000000
       0.075900     759.000000
       0.076000     760.000000
       0.076100     761.000000
       0.076200     762.000000
       0.076300     763.000000
       0.076400     764.000000
       0.076500     765.000000
       0.076600     766.000000
       0.076700     767.000000
       0.076800     768.000000
       0.076900     769.000000
       0.077000     770.000000
       0.077100     771.000000
       0.077200     772.000000
       0.077300     773.000000
       0.077400     774.000000
       0.077500     775.000000
       0.077600     776.000000
       0.077700     777.000000
       0.077800     778.000000
       0.077900     779.000000
       0.078000     780.000000
       0.078100     781.000000
       0.078200     782.000000
       0.078300     783.000000
       0.078400     784.000000
       0.078500     785.000000
       0.078600     786.000000
       0.078700     787.000000
       0.078800     788.000000
       0.078900     789.000000
       0.079000     790.000000
       0.079100     791.000000
       0.079200     792.000000
       0.079300     793.000000
       0.079400     794.000000
       0.079500     795.000000
       0.079600     796.000000
       0.079700     797.000000
       0.079800     798.000000
       0.079900     799.000000
       0.080000     800.000000
       0.080100     801.000000
       0.080200     802.000000
       0.080300     803.000000
       0.080400     804.000000
       0.080500     805.000000
       0.080600     806.000000
       0.080700     807.000000
       0.080800     808.000000
       0.080900     809.000000
       0.081000     810.000000
       0.081100     811.000000
       0.081200     812.000000
       0.081300     813.000000
       0.081400     814.000000
       0.081500     815.000000
       0.081600     816.000000
       0.081700     817.000000
       0.081800     818.000000
       0.081900     819.000000
       0.082000     820.000000
       0.082100     821.000000
       0.082200     822.000000
       0.082300     823.000000
       0.082400     824.000000
       0.082500     825.000000
       0.082600     826.000000
       0.082700     827.000000
       0.082800     828.000000
       0.082900     829.000000
       0.083000     830.000000
       0.083100     831.000000
       0.083200     832.000000
       0.083300     833.000000
       0.083400     834.000000
       0.083500     835.000000
       0.083600     836.000000
       0.083700     837.000000
       0.083800     838.000000
       0.083900     839.000000
       0.084000     840.000000
       0.084100     841.000000
       0.084200     842.000000
       0.084300     843.000000
       0.084400     844.000000
       0.084500     845.000000
       0.084600     846.000000
       0.084700     847.000000
       0.084800     848.000000
       0.084900     849.000000
       0.085000     850.000000
       0.085100     851.000000
       0.085200     852.000000
       0.085300     853.000000
       0.085400     854.000000
       0.085500     855.000000
       0.085600     856.000000
       0.085700     857.000000
       0.085800     858.000000
       0.085900     859.000000
       0.086000     860.000000
       0.086100     861.000000
       0.086200     862.000000
       0.086300     863.000000
       0.086400     864.000000
       0.086500     865.000000
       0.086600     866.000000
       0.086700     867.000000
       0.086800     868.000000
       0.086900     869.000000
       0.087000     870.000000
       0.087100     871.000000
       0.087200     872.000000
       0.087300     873.000000
       0.087400     874.000000
       0.087500     875.000000
       0.087600     876.000000
       0.087700     877.000000
       0.087800     878.000000
       0.087900     879.000000
       0.088000     880.000000
       0.088100     881.000000
       0.088200     882.000000
       0.088300     883.000000
       0.088400     884.000000
       0.088500     885.000000
       0.088600     886.000000
       0.088700     887.000000
       0.088800     888.000000
       0.088900     889.000000
       0.089000     890.000000
       0.089100     891.000000
       0.089200     892.000000
       0.089300     893.000000
       0.089400     894.000000
       0.089500     895.000000
       0.089600     896.000000
       0.089700     897.000000
       0.089800     898.000000
       0.089900     899.000000
       0.090000     900.000000
       0.090100     901.000000
       0.090200     902.000000
       0.090300     903.000000
       0.090400     904.000000
       0.090500     905.000000
       0.090600     906.000000
       0.090700     907.000000
       0.090800     908.000000
       0.090900     909.000000
       0.091000     910.000000
       0.091100     911.000000
       0.091200     912.000000
       0.091300     913.000000
       0.091400     914.000000
       0.091500     915.000000
       0.091600     916.000000
       0.091700     917.000000
       0.091800     918.000000
       0.091900     919.000000
       0.092000     920.000000
       0.092100     921.000000
       0.092200     922.000000
       0.092300     923.000000
       0.092400     924.000000
       0.092500     925.000000
       0.092600     926.000000
       0.092700     927.000000
       0.092800     928.000000
       0.092900     929.000000
       0.093000     930.000000
       0.093100     931.000000
       0.093200     932.000000
       0.093300     933.000000
       0.093400     934.000000
       0.093500     935.000000
       0.093600     936.000000
       0.093700     937.000000
       0.093800     938.000000
       0.093900     939.000000
       0.094000     940.000000
       0.094100     941.000000
       0.094200     942.000000
       0.094300     943.000000
       0.094400     944.000000
       0.094500     945.000000
       0.094600     946.000000
       0.094700     947.000000
       0.094800     948.000000
       0.094900     949.000000
       0.095000     950.000000
       0.095100     951.000000
       0.095200     952.000000
       0.095300     953.000000
       0.095400     954.000000
       0.095500     955.000000
       0.095600     956.000000
       0.095700     957.000000
       0.095800     958.000000
       0.095900     959.000000
       0.096000     960.000000
       0.096100     961.000000
       0.096200     962.000000
       0.096300     963.000000
       0.096400     964.000000
       0.096500     965.000000
       0.096600     966.000000
       0.096700     967.000000
       0.096800     968.000000
       0.096900     969.000000
       0.097000     970.000000
       0.097100     971.000000
       0.097200     972.000000
       0.097300     973.000000
       0.097400     974.000000
       0.097500     975.000000
       0.097600     976.000000
       0.097700     977.000000
       0.097800     978.000000
       0.097900     979.000000
       0.098000     980.000000
       0.098100     981.000000
       0.098200     982.000000
       0.098300     983.000000
       0.098400     984.000000
       0.098500     985.000000
       0.098600     986.000000
       0.098700     987.000000
       0.098800     988.000000
       0.098900     989.000000
       0.099000     990.000000
       0.099100     991.000000
       0.099200     992.000000
       0.099300     993.000000
       0.099400     994.000000
       0.099500     995.000000
       0.099600     996.000000
       0.099700     997.000000
       0.099800     998.000000
       0.099900     999.000000
       0.100000    1000.000000